#VRML_SIM R2023b utf8
# license: Apache License 2.0
# license url: http://www.apache.org/licenses/LICENSE-2.0
# This is a proto file for Webots for the Rebel

PROTO Rebel [
  field  SFVec3f     translation     0 0 0
  field  SFRotation  rotation        0 0 1 0
  field  SFString    name            "Rebel"      # Is `Robot.name`.
  field  SFString    controller      "void"       # Is `Robot.controller`.
  field  MFString    controllerArgs  []           # Is `Robot.controllerArgs`.
  field  SFString    customData      ""           # Is `Robot.customData`.
  field  SFBool      supervisor      FALSE        # Is `Robot.supervisor`.
  field  SFBool      synchronization TRUE         # Is `Robot.synchronization`.
  field  SFBool      selfCollision   FALSE        # Is `Robot.selfCollision`.
]
{
  Robot {
    translation IS translation
    rotation IS rotation
    controller IS controller
    controllerArgs IS controllerArgs
    customData IS customData
    supervisor IS supervisor
    synchronization IS synchronization
    selfCollision IS selfCollision
    children [
      Solid {
        children [
          DEF Robolink_RebeL_000_visual CadShape {
            url "../meshes/robolink_rebel/Robolink_RebeL_000.dae"
          }
          HingeJoint {
            jointParameters HingeJointParameters {
              axis 0.000000 -0.000000 -1.000000
              anchor 0.000000 0.000000 0.126000
            }
            device [
              RotationalMotor {
                name "joint1"
                maxVelocity 2.16
                minPosition -3.12414
                maxPosition 3.12414
                maxTorque 330.0
              }
              PositionSensor {
                name "joint1_sensor"
              }
            ]
            endPoint Solid {
              translation 0.000000 0.000000 0.126000
              rotation -0.000000 0.000000 1.000000 3.141600
              children [
                Pose {
                  translation 0.000000 0.000000 -0.053700
                  rotation -0.000000 0.000000 1.000000 3.141600
                  children [
                    DEF Robolink_RebeL_001_visual CadShape {
                      url "../meshes/robolink_rebel/Robolink_RebeL_001.dae"
                    }
                  ]
                }
                HingeJoint {
                  jointParameters HingeJointParameters {
                    axis 0.000000 -1.000000 0.000000
                    anchor 0.000000 0.025000 0.153000
                  }
                  device [
                    RotationalMotor {
                      name "joint2"
                      maxVelocity 2.16
                      minPosition -1.48353
                      maxPosition 2.44346
                      maxTorque 330.0
                    }
                    PositionSensor {
                      name "joint2_sensor"
                    }
                  ]
                  endPoint Solid {
                    translation 0.000000 0.025000 0.153000
                    children [
                      Pose {
                        translation 0.000000 -0.005000 -0.006250
                        rotation -1.000000 0.000000 0.000000 1.570700
                        children [
                          DEF Robolink_RebeL_002_0_visual CadShape {
                            url "../meshes/robolink_rebel/Robolink_RebeL_002_0.dae"
                          }
                        ]
                      }
                      Solid {
                        translation 0.000000 -0.025000 0.100000
                        children [
                          Pose {
                            translation 0.000000 -0.006250 -0.006250
                            rotation -0.000000 0.000000 1.000000 3.141600
                            children [
                              DEF Robolink_RebeL_002_1_visual CadShape {
                                url "../meshes/robolink_rebel/Robolink_RebeL_002_1.dae"
                              }
                            ]
                          }
                          Solid {
                            translation -0.032600 0.000000 0.056460
                            rotation 0.000000 -1.000000 0.000000 1.047200
                            children [
                              Pose {
                                translation 0.000000 0.000000 -0.006250
                                rotation 0.000000 -0.000000 -1.000000 3.141600
                                children [
                                  DEF Robolink_RebeL_002_2_visual CadShape {
                                    url "../meshes/robolink_rebel/Robolink_RebeL_002_2.dae"
                                  }
                                ]
                              }
                              HingeJoint {
                                jointParameters HingeJointParameters {
                                  axis 0.000000 -1.000000 0.000000
                                  anchor 0.000000 0.025000 0.100000
                                }
                                device [
                                  RotationalMotor {
                                    name "joint3"
                                    maxVelocity 2.16
                                    minPosition -1.39626
                                    maxPosition 2.61799
                                    maxTorque 330.0
                                  }
                                  PositionSensor {
                                    name "joint3_sensor"
                                  }
                                ]
                                endPoint Solid {
                                  translation 0.000000 0.025000 0.100000
                                  children [
                                    Pose {
                                      translation 0.000000 -0.008000 -0.008000
                                      rotation -1.000000 0.000000 0.000000 1.570700
                                      children [
                                        DEF Robolink_RebeL_003_visual CadShape {
                                          url "../meshes/robolink_rebel/Robolink_RebeL_003.dae"
                                        }
                                      ]
                                    }
                                    HingeJoint {
                                      jointParameters HingeJointParameters {
                                        axis 0.000000 0.000000 1.000000
                                        anchor 0.000000 -0.025000 0.153000
                                      }
                                      device [
                                        RotationalMotor {
                                          name "joint4"
                                          maxVelocity 2.16
                                          minPosition -3.12414
                                          maxPosition 3.12414
                                          maxTorque 330.0
                                        }
                                        PositionSensor {
                                          name "joint4_sensor"
                                        }
                                      ]
                                      endPoint Solid {
                                        translation 0.000000 -0.025000 0.153000
                                        children [
                                          Pose {
                                            translation 0.000000 0.000000 -0.003125
                                            children [
                                              DEF Robolink_RebeL_004_visual CadShape {
                                                url "../meshes/robolink_rebel/Robolink_RebeL_004.dae"
                                              }
                                            ]
                                          }
                                          HingeJoint {
                                            jointParameters HingeJointParameters {
                                              axis 0.000000 -1.000000 0.000000
                                              anchor 0.000000 0.029000 0.143000
                                            }
                                            device [
                                              RotationalMotor {
                                                name "joint5"
                                                maxVelocity 2.16
                                                minPosition -1.65806
                                                maxPosition 1.65806
                                                maxTorque 330.0
                                              }
                                              PositionSensor {
                                                name "joint5_sensor"
                                              }
                                            ]
                                            endPoint Solid {
                                              translation 0.000000 0.029000 0.143000
                                              children [
                                                Pose {
                                                  translation 0.000000 -0.006250 0.000000
                                                  rotation 0.577178 0.577234 -0.577638 2.093880
                                                  children [
                                                    DEF Robolink_RebeL_005_visual CadShape {
                                                      url "../meshes/robolink_rebel/Robolink_RebeL_005.dae"
                                                    }
                                                  ]
                                                }
                                                HingeJoint {
                                                  jointParameters HingeJointParameters {
                                                    axis 0.000000 0.000000 1.000000
                                                    anchor 0.000000 -0.029000 0.118800
                                                  }
                                                  device [
                                                    RotationalMotor {
                                                      name "joint6"
                                                      maxVelocity 2.16
                                                      minPosition -3.12414
                                                      maxPosition 3.12414
                                                      maxTorque 330.0
                                                    }
                                                    PositionSensor {
                                                      name "joint6_sensor"
                                                    }
                                                  ]
                                                  endPoint Solid {
                                                    translation 0.000000 -0.029000 0.118800
                                                    children [
                                                      Pose {
                                                        translation 0.000000 0.000000 -0.006250
                                                        rotation 0.000000 -1.000000 0.000000 1.570000
                                                        children [
                                                          DEF Robolink_RebeL_006_visual CadShape {
                                                            url "../meshes/robolink_rebel/Robolink_RebeL_006.dae"
                                                          }
                                                        ]
                                                      }
                                                    ]
                                                    name "rebel_link8"
                                                    boundingObject DEF Robolink_RebeL_006 Mesh {
                                                      url "../meshes/robolink_rebel/Robolink_RebeL_006.dae"
                                                    }
                                                    physics Physics {
                                                      density -1
                                                      mass 0.100000
                                                      centerOfMass [ 0.000000 0.000000 0.000000 ]
                                                      inertiaMatrix [
                                                        3.000000e-02 3.000000e-02 3.000000e-02
                                                        0.000000e+00 0.000000e+00 0.000000e+00
                                                      ]
                                                    }
                                                  }
                                                }
                                              ]
                                              name "rebel_link7"
                                              boundingObject DEF Robolink_RebeL_005 Mesh {
                                                url "../meshes/robolink_rebel/Robolink_RebeL_005.dae"
                                              }
                                              physics Physics {
                                                density -1
                                                mass 0.100000
                                                centerOfMass [ 0.000000 0.000000 0.000000 ]
                                                inertiaMatrix [
                                                  3.000000e-02 3.000000e-02 3.000000e-02
                                                  0.000000e+00 0.000000e+00 0.000000e+00
                                                ]
                                              }
                                            }
                                          }
                                        ]
                                        name "rebel_link6"
                                        boundingObject DEF Robolink_RebeL_004 Mesh {
                                          url "../meshes/robolink_rebel/Robolink_RebeL_004.dae"
                                        }
                                        physics Physics {
                                          density -1
                                          mass 0.100000
                                          centerOfMass [ 0.000000 0.000000 0.000000 ]
                                          inertiaMatrix [
                                            3.000000e-02 3.000000e-02 3.000000e-02
                                            0.000000e+00 0.000000e+00 0.000000e+00
                                          ]
                                        }
                                      }
                                    }
                                  ]
                                  name "rebel_link5"
                                  boundingObject DEF Robolink_RebeL_003 Mesh {
                                    url "../meshes/robolink_rebel/Robolink_RebeL_003.dae"
                                  }
                                  physics Physics {
                                    density -1
                                    mass 0.100000
                                    centerOfMass [ 0.000000 0.000000 0.000000 ]
                                    inertiaMatrix [
                                      3.000000e-02 3.000000e-02 3.000000e-02
                                      0.000000e+00 0.000000e+00 0.000000e+00
                                    ]
                                  }
                                }
                              }
                            ]
                            name "rebel_link4"
                            boundingObject DEF Robolink_RebeL_002_2 Mesh {
                              url "../meshes/robolink_rebel/Robolink_RebeL_002_2.dae"
                            }
                            physics Physics {
                              density -1
                              mass 0.100000
                              centerOfMass [ 0.000000 0.000000 0.000000 ]
                              inertiaMatrix [
                                3.000000e-02 3.000000e-02 3.000000e-02
                                0.000000e+00 0.000000e+00 0.000000e+00
                              ]
                            }
                          }
                        ]
                        name "rebel_link3"
                        boundingObject DEF Robolink_RebeL_002_1 Mesh {
                          url "../meshes/robolink_rebel/Robolink_RebeL_002_1.dae"
                        }
                        physics Physics {
                          density -1
                          mass 0.100000
                          centerOfMass [ 0.000000 0.000000 0.000000 ]
                          inertiaMatrix [
                            3.000000e-02 3.000000e-02 3.000000e-02
                            0.000000e+00 0.000000e+00 0.000000e+00
                          ]
                        }
                      }
                    ]
                    name "rebel_link2"
                    boundingObject DEF Robolink_RebeL_002_0 Mesh {
                      url "../meshes/robolink_rebel/Robolink_RebeL_002_0.dae"
                    }
                    physics Physics {
                      density -1
                      mass 0.100000
                      centerOfMass [ 0.000000 0.000000 0.000000 ]
                      inertiaMatrix [
                        3.000000e-02 3.000000e-02 3.000000e-02
                        0.000000e+00 0.000000e+00 0.000000e+00
                      ]
                    }
                  }
                }
              ]
              name "rebel_link1"
              boundingObject DEF Robolink_RebeL_001 Mesh {
                url "../meshes/robolink_rebel/Robolink_RebeL_001.dae"
              }
              physics Physics {
                density -1
                mass 0.100000
                centerOfMass [ 0.000000 0.000000 0.000000 ]
                inertiaMatrix [
                  3.000000e-02 3.000000e-02 3.000000e-02
                  0.000000e+00 0.000000e+00 0.000000e+00
                ]
              }
            }
          }
        ]
        name "base_link"
        boundingObject DEF Robolink_RebeL_000 Mesh {
          url "../meshes/robolink_rebel/Robolink_RebeL_000.dae"
        }
        physics Physics {
          density -1
          mass 1.000000
          centerOfMass [ 0.000000 0.000000 0.000000 ]
        }
      }
    ]
    name IS name
  }
}
